Workbook

Sheet Kas Fisik Bahan Baku
A1: LAPORAN BELANJA BAHAN BAKU
A2: KOPERASI GOTONG ROYONG SEJAHTERA NUSANTARA
A3: MEI 2026
A6: TANGGAL | B6: NO | C6: NAMA TOKO | D6: NAMA BARANG | E6: SATUAN | F6: QTY | G6: HARGA | H6: SUBTOTAL | I6: TOTAL | J6: ADMIN
A7: 24 Mei 2026 | H7: TOTAL | I7: =sum(I8:I42) -> 10990000 | J7: =sum(J8:J42) -> 20000
C8: RICHARD TANTAMA | D8: KNOOR CHICK POWDER | E8: KG | F8: 6 | G8: =H8/F8 -> 94000 | H8: 564000 | I8: =H8 -> 564000 | K8: v
C9: DINAWATI | D9: BAMER KULIT | E9: KG | F9: 9 | G9: 36000 | H9: =F9*G9 -> 324000
D10: BAMER KUPAS | E10: KG | F10: 3 | G10: 40000 | H10: =F10*G10 -> 120000
D11: BAPUT KUPAS | E11: KG | F11: 8 | G11: 30000 | H11: =F11*G11 -> 240000 | I11: =SUM(H9:H11) -> 684000 | K11: v
C12: PT. BERKAT SINERGI TERPADU | D12: BOMBAY CAMBRIDGE 50/60 CRB | E12: KARUNG | F12: 20 | G12: =H12/F12 -> 19000 | H12: 380000 | I12: =H12 -> 380000 | K12: v
C13: AMMIRUDIN | D13: KOL | E13: KG | F13: 60 | G13: 7500 | H13: =F13*G13 -> 450000 | I13: =H13 -> 450000 | K13: v
C14: SRI WATI | D14: BUNCIS | E14: KG | F14: 80 | G14: 20000 | H14: =F14*G14 -> 1600000
D15: CABE MERAH | E15: KG | F15: 6 | G15: 70000 | H15: =F15*G15 -> 420000
D16: RAWIT MERAH | E16: KG | F16: 5 | G16: 90000 | H16: =F16*G16 -> 450000
D17: DAUN BAWANG | E17: KG | F17: 4 | G17: 15000 | H17: =F17*G17 -> 60000
D18: JAHE | E18: KG | F18: 2 | G18: 20000 | H18: =F18*G18 -> 40000
D19: CESIM | E19: KG | F19: 20 | G19: 6000 | H19: =F19*G19 -> 120000
D20: TIMUN | E20: KG | F20: 105 | G20: 8000 | H20: =F20*G20 -> 840000
D21: WORTEL | E21: KG | F21: 142 | G21: 12000 | H21: =F21*G21 -> 1704000
D22: PAKCOY | E22: KG | F22: 90 | G22: 10000 | H22: =F22*G22 -> 900000 | I22: =SUM(H14:H22) -> 6134000 | K22: v
C23: RUSDIANTO | D23: LAOS | E23: KG | F23: 2 | G23: =H23/F23 -> 12000 | H23: 24000
D24: SEREH | E24: KG | F24: 2 | G24: =H24/F24 -> 10000 | H24: 20000
D25: KUNIR | E25: KG | F25: 1 | G25: =H25/F25 -> 12000 | H25: 12000
D26: SALAM | E26: KG | F26: 1 | G26: =H26/F26 -> 14000 | H26: 14000 | I26: =SUM(H23:H26) -> 70000 | K26: v
C27: ADE SETIAWAN | D27: TOMAT | E27: KG | F27: 30 | G27: 12000 | H27: =F27*G27 -> 360000 | I27: =H27 -> 360000 | K27: v
C28: H.ZAENAL | D28: GULA PUTIH | E28: KG | F28: 20 | G28: 18500 | H28: =F28*G28 -> 370000
D29: KECAP INGGRIS | E29: KG | F29: 1 | G29: 47000 | H29: =F29*G29 -> 47000
D30: BANGO 1.5 | E30: BOTOL | F30: 4 | G30: 48000 | H30: =F30*G30 -> 192000
D31: KEMIRI | E31: PCS | F31: 2 | G31: 43000 | H31: =F31*G31 -> 86000
D32: LADA HITAM | E32: KG | F32: 0.25 | G32: =H32/F32 -> 180000 | H32: 45000
D33: ROYCO | E33: KG | F33: 3 | G33: 42000 | H33: =F33*G33 -> 126000
D34: SAOS TOMAT | E34: DRIGEN | F34: 1 | G34: 95000 | H34: =F34*G34 -> 95000
D35: SAOS CILLI | E35: DRIGEN | F35: 1 | G35: 115000 | H35: =F35*G35 -> 115000
D36: SAOS TIRAM | E36: BOTOL | F36: 6 | G36: 52000 | H36: =F36*G36 -> 312000
D37: TERASI 1/2 KG | E37: PCS | F37: 2 | G37: 6000 | H37: =F37*G37 -> 12000
D38: TERIGU | E38: SAK | F38: 2 | G38: 225000 | H38: =F38*G38 -> 450000
D39: MAYZENA | E39: KG | F39: 2 | G39: 24000 | H39: =F39*G39 -> 48000
D40: GARAM | E40: BAL | F40: 1 | G40: 70000 | H40: =F40*G40 -> 70000
D41: KECAP BANGO | E41: DRIGEN | F41: 2 | G41: 190000 | H41: =F41*G41 -> 380000 | I41: =SUM(H28:H41) -> 2348000 | K41: v
D42: ADMIN | F42: 8 | G42: 2500 | H42: =F42*G42 -> 20000 | J42: =H42 -> 20000
...

Sheet Kas Fisik Oprasional
A1: LAPORAN BELANJA OPERASIONAL
A2: KOPERASI GOTONG ROYONG SEJAHTERA NUSANTARA
A3: MEI 2026
A6: TANGGAL | B6: NO | C6: NAMA TOKO | D6: NAMA BARANG | E6: SATUAN | F6: QTY | G6: HARGA | H6: SUBTOTAL | I6: TOTAL | J6: ADMIN
A7: 24 Mei 2026 | H7: TOTAL | I7: =sum(I8:I17) -> 1547500 | J7: =sum(J8:J17) -> 5000
C8: TK JAYA | D8: HIT SEMPROT BESAR | E8: BOTOL | F8: 5 | G8: 32500 | H8: =F8*G8 -> 162500
D9: TISU MUKA PASEO | E9: PACK | F9: 10 | G9: 9000 | H9: =F9*G9 -> 90000
D10: WIPOL BOTOL BESAR | E10: BOTOL | F10: 15 | G10: 20000 | H10: =F10*G10 -> 300000
D11: KIT SABUN MOTOR | E11: PACK | F11: 1 | G11: 15000 | H11: =F11*G11 -> 15000
D12: SOKLIN PEL SEREH | E12: DRIGEN | F12: 3 | G12: 53000 | H12: =F12*G12 -> 159000 | I12: =sum(H8:H12) -> 726500 | K12: v
C13: TK ANYAR | D13: STIK ESKRIM | E13: PACK | F13: 8 | G13: 16000 | H13: =F13*G13 -> 128000
D14: PLASTIK PP 10X25 02 | E14: PACK | F14: 11 | G14: 11000 | H14: =F14*G14 -> 121000
D15: PLASTIK ES 15X35 | E15: PACK | F15: 4 | G15: 13000 | H15: =F15*G15 -> 52000
D16: CUP SAMBAL 35 ML | E16: PACK | F16: 40 | G16: 13000 | H16: =F16*G16 -> 520000 | I16: =sum(H13:H16) -> 821000 | K16: v
D17: ADMIN | F17: 2 | G17: 2500 | H17: =F17*G17 -> 5000 | J17: =H17 -> 5000
A18: 25 Mei 2026 | H18: TOTAL | I18: =sum(I19:I34) -> 4838400 | J18: =sum(J19:J34) -> 12500
C19: TK SINAR JAYA | D19: ALAT KUPAS WORTEL | E19: PCS | F19: 8 | G19: 6000 | H19: =F19*G19 -> 48000
D20: ALAT KOCOKAN TELOR | E20: PCS | F20: 1 | G20: 20000 | H20: =F20*G20 -> 20000
D21: LAP MICROFIBER ISI 10 KLEANER | E21: PCS | F21: 5 | G21: 96700 | H21: =F21*G21 -> 483500
D22: LAP KANEBO | E22: PCS | F22: 4 | G22: 10000 | H22: =F22*G22 -> 40000
D23: PAYUNG | E23: PCS | F23: 5 | G23: 25500 | H23: =F23*G23 -> 127500 | I23: =sum(H19:H23) -> 719000 | K23: v
C24: TK SANITAS | D24: KAPORIT BUBUK (15 kg) | E24: EMBER | F24: 1 | G24: 470000 | H24: =F24*G24 -> 470000 | I24: =H24 -> 470000 | K24: v
C25: TK EKA KNMN | D25: PLASTIK HDPLONG | E25: PACK | F25: 10.3 | G25: 48000 | H25: =F25*G25 -> 494400
D26: THINWAL KOTAK 500 ML (500 PCS) | E26: KARDUS | F26: 2 | G26: 505000 | H26: =F26*G26 -> 1010000
D27: THINWAL KOTAK 500 ML | E27: PACK | F27: 14 | G27: 26500 | H27: =F27*G27 -> 371000
D28: PLASTIK ES 12X25 (4 PACK) | E28: IKAT | F28: 20 | G28: 39500 | H28: =F28*G28 -> 790000
D29: PLASTIK ES 10X26 | E29: IKAT | F29: 5 | G29: 39500 | H29: =F29*G29 -> 197500
D30: STIK ES KRIM | E30: PACK | F30: 5 | G30: 15000 | H30: =F30*G30 -> 75000
D31: PLASTIK PP 40X60 RAMAYANA | E31: PACK | F31: 1 | G31: 43000 | H31: =F31*G31 -> 43000 | I31: =sum(H25:H31) -> 2980900 | K31: v
C32: TK SAMUDRA | D32: SARUNG TANGAN KAIN | E32: LUSIN | F32: 1 | G32: 28500 | H32: =F32*G32 -> 28500 | I32: =H32 -> 28500 | K32: v
C33: TK SEMARANG | D33: JENGKOK PLASTIK LION STAR | E33: PCS | F33: 16 | G33: 40000 | H33: =F33*G33 -> 640000 | I33: =H33 -> 640000 | K33: v
D34: ADMIN | F34: 5 | G34: 2500 | H34: =F34*G34 -> 12500 | J34: =H34 -> 12500
A35: 28 Mei 2026 | H35: TOTAL | I35: =sum(I36:I42) -> 3678000 | J35: =sum(J36:J51) -> 7500
C36: RIZKI FADILLAH | D36: GAS 50KG TEGALSARI | E36: TABUNG | F36: 1 | G36: 1125000 | H36: =F36*G36 -> 1125000
C37: RIZKI FADILLAH | D37: GAS 50KG BAKUNG 01 | E37: TABUNG | F37: 2 | G37: 1125000 | H37: =F37*G37 -> 2250000 | I37: =sum(H36:H37) -> 3375000 | K37: v
C38: NUR AISYAH | D38: SESER IKAN 30 CM | F38: 1 | G38: 30000
D39: SESER IKAN 15 CM | F39: 1 | G39: 15000
D40: EMBER 69CM | F40: 4 | G40: 180000
D41: GELAS PLASTIK HAWAI | F41: 12 | G41: 78000 | H41: =SUM(G38:G41) -> 303000 | I41: =H41 -> 303000 | K41: v
D42: ADMIN | F42: 2 | G42: 2500 | H42: =F42*G42 -> 5000 | J42: =H42 -> 5000
...

Sheet list Reimburse
A1: LIST REIMBURSE
A2: KOPERASI GOTONG ROYONG SEJAHTERA NUSANTARA
A3: MEI 2026
A6: TANGGAL | B6: NO | C6: NAMA TOKO | D6: NAMA BARANG | E6: SATUAN | F6: QTY | G6: HARGA | H6: SUBTOTAL | I6: TOTAL | J6: ADMIN | K6: =I7+I10+I12+I15+I32+I37+I45+I48+I57+I70+I72+I83+I86+I89+I94+I99 -> 8308150
A7: 25 Mei 2026 | H7: TOTAL | I7: =sum(I8:I9) -> 264000 | J7: =sum(J8:J9) -> 2500
C8: FIA BINAWAN | D8: AYAM | E8: Kg | F8: 8 | G8: 33000 | H8: =F8*G8 -> 264000 | I8: =H8 -> 264000 | K8: v
D9: ADMIN | F9: 1 | G9: 2500 | H9: =F9*G9 -> 2500 | J9: =H9 -> 2500
A10: 28 Mei 2026 | H10: TOTAL | I10: =sum(I11) -> 105000 | J10: =sum(J11) -> 0
A11: 25 Mei | C11: WERKUDARA | D11: GULA | E11: KG | F11: 6 | G11: 17500 | H11: =F11*G11 -> 105000 | I11: =H11 -> 105000 | K11: v
A12: 31 Mei 2026 | H12: TOTAL | I12: =SUM(I13:I14) -> 90000 | J12: =SUM(J13:J14) -> 0
A13: 25 Mei | C13: GUNADI KALIKOA | D13: BAWANG BOMBAY | E13: KG | F13: 3.45 | G13: 30000 | H13: =F13*G13 -> 103500
H14: -13500 | I14: =SUM(H13:H14) -> 90000 | K14: v
A15: 1 Juni 2026 | H15: TOTAL | I15: =SUM(I16:I31) -> 1517600 | J15: =SUM(J16:J31) -> 0
C16: FIA BINAWAN | D16: BAWANG MERAH | E16: KG | F16: 1 | G16: 56000 | H16: =F16*G16 -> 56000
D17: GULA PASIR | E17: KG | F17: 1 | G17: 22000 | H17: =F17*G17 -> 22000 | I17: =SUM(H16:H17) -> 78000 | K17: v
C18: BAKUNG 2 | D18: PARKIR | E18: PCS | F18: 1 | G18: 3000 | H18: =F18*G18 -> 3000
D19: TEFLON | E19: PCS | F19: 4 | G19: 164000 | H19: =F19*G19 -> 656000 | I19: =SUM(H18:H19) -> 659000 | K19: v
A20: 23 Mei | C20: ULVI KALIKOA | D20: BERAS | F20: 1 | G20: 16000 | H20: =F20*G20 -> 16000
A21: 26 mei | D21: GARAM | F21: 1 | G21: 20000 | H21: =F21*G21 -> 20000
A22: 26 mei | D22: PECAY | F22: =H22/G22 -> 3.3333333 | G22: 12000 | H22: 40000
A23: 26 mei | D23: WORTEL | F23: 5 | G23: 16000 | H23: =F23*G23 -> 80000
A24: 29 Mei | D24: BERAS PREMIUM | E24: KG | F24: 10 | G24: 15500 | H24: =F24*G24 -> 155000
A25: 29 Mei | D25: GARAM | E25: PCS | F25: 2 | G25: 3000 | H25: =F25*G25 -> 6000
A26: 29 MEI | D26: MC LEWIS TOMATO | E26: DRIGEN | F26: 2 | G26: 75500 | H26: =F26*G26 -> 151000 | I26: =SUM(H20:H26) -> 468000 | K26: V
D27: TAHU | E27: PCS | F27: 200 | G27: 700 | H27: =F27*G27 -> 140000 | I27: =H27 -> 140000 | K27: V
A28: 25 Mei | C28: HASBI BAKUNG 1 | D28: PLASTIK | E28: PCS | F28: 1 | G28: 500 | H28: =F28*G28 -> 500
D29: KECAP SEDAP | E29: PCS | F29: 4 | G29: 26900 | H29: =F29*G29 -> 107600
D30: BANGO 700 | E30: PCS | F30: 3 | G30: 26900 | H30: =F30*G30 -> 80700
D31: DISKON | G31: -16200 | H31: =G31 -> -16200 | I31: =SUM(H28:H31) -> 172600 | K31: V
A32: 5 Juni 2026 | H32: TOTAL | I32: =SUM(I33:I36) -> 682500 | J32: =SUM(J33:J36) -> 0
C33: TEGALSARI | D33: TELUR 03 JUNI | E33: KG | F33: 10 | G33: 25500 | H33: =F33*G33 -> 255000
D34: TELUR 03 JUNI | E34: KG | F34: 5 | G34: 25500 | H34: =F34*G34 -> 127500
D35: TELUR 04 JUNI | E35: KG | F35: 12 | G35: 25500 | H35: =F35*G35 -> 306000
D36: DISKON | H36: -6000 | I36: =SUM(H33:H36) -> 682500 | K36: v
A37: 7 Juni 2026 | H37: TOTAL | I37: =SUM(I38:I44) -> 302600 | J37: =SUM(J38:J44) -> 0
C38: ULVI KALIKOA | D38: TELUR 03 JUNI | E38: KG | F38: 3 | G38: =H38/F38 -> 27000 | H38: 81000
D39: NORI 04 JUNI | E39: PCS | F39: 3 | G39: 16700 | H39: =F39*G39 -> 50100
D40: NORI 04 JUNI | E40: PCS | F40: 2 | G40: 17500 | H40: =F40*G40 -> 35000
D41: PLASTIK | E41: PCS | F41: 1 | G41: 500 | H41: =F41*G41 -> 500
D42: DELMONTE TOMAT 04 JUNI | E42: KG | F42: 1 | G42: 17500 | H42: =F42*G42 -> 17500
...

Sheet Hutang Suplier
A1: TANGGAL | B1: NO | C1: NAMA TOKO | D1: NAMA BARANG | E1: SATUAN | F1: QTY | G1: HARGA | H1: Disc | I1: SUBTOTAL | J1: TOTAL | K1: Pengecekan Invoice | L1: REKENING
A2: 20-21 April | C2: Fandy Sumantri | D2: Bahan Baku Beras Dan Minyak | F2: 1 | G2: 31445000 | I2: =F2*G2 -> 31445000 | J2: =I2 -> 31445000 | K2: SUDAH APPROVE
A3: 46139 | C3: Widia | D3: Semangka | F3: 225 | G3: 18500 | I3: =F3*G3 -> 4162500
C4: Widia | D4: Santang | F4: 26 | G4: 315000 | I4: =F4*G4 -> 8190000
C5: Widia | D5: Ambon Super | F5: 1946 | G5: 1800 | I5: =F5*G5 -> 3502800 | J5: =SUM(I3:I5) -> 15855300 | K5: SUDAH APPROVE
A6: 46140 | C6: Jaena | D6: Ayam Potong | F6: 200 | G6: 34000 | I6: =F6*G6 -> 6800000
C7: Jaena | D7: Ayam Fillet | F7: 90 | G7: 45000 | I7: =F7*G7 -> 4050000
C8: Jaena | D8: Ayam Fillet | F8: 10 | G8: 45000 | I8: =F8*G8 -> 450000
A9: 46141 | C9: Jaena | D9: Filet tanpa kulit | F9: 120 | G9: 47000 | I9: =F9*G9 -> 5640000
C10: Jaena | D10: Ayam Potong | F10: 135 | G10: 35000 | I10: =F10*G10 -> 4725000
A11: 01 Mei | C11: Jaena | D11: Ayam Utuh | F11: 165 | G11: 35000 | I11: =F11*G11 -> 5775000 | J11: =SUM(I6:I11) -> 27440000 | K11: SUDAH APPROVE
A12: 46138 | C12: Jaena | D12: tempe tegalsari | F12: 85 | G12: 12000 | I12: =F12*G12 -> 1020000
A13: 46139 | C13: Jaena | D13: tahu tegalsari | F13: 1540 | G13: 750 | I13: =F13*G13 -> 1155000
A14: 46140 | C14: Jaena | D14: tempe tegalsari | F14: 85 | G14: 12000 | I14: =F14*G14 -> 1020000
A15: 46141 | C15: Jaena | D15: Tahu Tegalsari | F15: 1790 | G15: 500 | I15: =F15*G15 -> 895000 | J15: =SUM(I12:I15) -> 4090000 | K15: SUDAH APPROVE
A16: 26-29 April | C16: Ishma | D16: tahu bakung, binawan, werkudara | F16: 1 | G16: 13542000 | I16: =F16*G16 -> 13542000 | J16: =I16 -> 13542000 | K16: SUDAH APPROVE
A17: 46140 | C17: Ishma | D17: Tempe bakung 1 | F17: 120 | G17: 12000 | I17: =F17*G17 -> 1440000
A18: 46141 | C18: Ishma | D18: Tempe bakung 2 | F18: 65 | G18: 12000 | I18: =F18*G18 -> 780000 | J18: =SUM(I17:I18) -> 2220000 | K18: SUDAH APPROVE
A20: 1 Mei 2026 | C20: Dwinanto Basarah | D20: Tempe Kalikoa | F20: 53 | G20: 12000 | I20: =G20*F20 -> 636000
A21: 04 Mei | C21: Dwinanto Basarah | D21: Tempe Werkudara | F21: 81 | G21: 12000 | I21: =G21*F21 -> 972000
C22: Dwinanto Basarah | D22: Tempe Kalikoa | F22: 85 | G22: 12000 | I22: =G22*F22 -> 1020000 | J22: =SUM(I20:I22) -> 2628000 | K22: SUDAH APPROVE
A24: 46141 | C24: Rizki Fadillah | D24: Gas Werkudara | F24: 1 | G24: 1125000 | I24: =G24*F24 -> 1125000 | J24: =I24 -> 1125000 | K24: SUDAH APPROVE
A26: 46141 | C26: Yudi | D26: Ayam Fillet Tegalsari | F26: 109 | G26: 52500 | I26: =G26*F26 -> 5722500 | J26: =I26 -> 5722500 | K26: SUDAH APPROVE | L26: 782002200300 RADEN YUDI PRAMANTO CIMB Niaga
A27: 03 Mei | C27: Yudi | D27: Ayam Potong Tegalsari | F27: 179 | G27: 36500 | I27: =G27*F27 -> 6533500 | J27: =SUM(I26:I27) -> 12256000 | K27: SUDAH APPROVE
A28: 46138 | C28: Riski Fadilah | D28: Pisang Kalikoa | F28: 1700 | G28: 1550 | I28: =F28*G28 -> 2635000 | L28: RIZKY FADILLAH
A29: 46139 | C29: Riski Fadilah | D29: Jeruk Medan Tegalsari | F29: 156 | G29: 29500 | I29: =F29*G29 -> 4602000 | L29: 7257935757
A30: 46140 | C30: Riski Fadilah | D30: Jeruk Medan Werkudara | F30: 138.3 | G30: 29500 | I30: =F30*G30 -> 4079850
A31: 46138 | C31: Riski Fadilah | D31: Semangka Tegalsari | F31: 127 | G31: 13500 | I31: =F31*G31 -> 1714500
A32: 46139 | C32: Riski Fadilah | D32: Buah Naga Werkudara | F32: 220.5 | G32: 21000 | I32: =F32*G32 -> 4630500
A33: 46140 | C33: Riski Fadilah | D33: Pisang Kalikoa | F33: 1680 | G33: 1550 | I33: =F33*G33 -> 2604000
A34: 46140 | C34: Riski Fadilah | D34: Sunkis Tegalsari | F34: 98 | G34: 34000 | I34: =F34*G34 -> 3332000 | J34: =SUM(I28:I34) -> 23597850 | K34: SUDAH APPROVE
A35: 46139 | C35: Riski Fadilah | D35: Jeruk Medan Kalikoa | F35: 140 | G35: 29500 | I35: =F35*G35 -> 4130000
A36: 46139 | C36: Riski Fadilah | D36: Pisang Binawan | F36: 400 | G36: 1550 | I36: =F36*G36 -> 620000
A37: 46141 | C37: Riski Fadilah | D37: Anggur Tegalsari | F37: 45 | G37: 84000 | I37: =F37*G37 -> 3780000
C38: Riski Fadilah | D38: Jeruk Kino | F38: 140 | G38: 33500 | I38: =F38*G38 -> 4690000
C39: Riski Fadilah | D39: Pisang | F39: 1390 | G39: 1550 | I39: =F39*G39 -> 2154500
A40: 1 Mei | C40: Riski Fadilah | D40: Anggur Kalikoa | F40: 18 | G40: 84000 | I40: =F40*G40 -> 1512000
A41: 46141 | C41: Riski Fadilah | D41: Jambu Kalikoa | F41: 175 | G41: 12000 | I41: =F41*G41 -> 2100000
A42: 1 Mei | C42: Riski Fadilah | D42: Jeruk Medan Binawan | F42: 107 | G42: 29500 | I42: =F42*G42 -> 3156500 | J42: =SUM(I35:I42) -> 22143000 | K42: SUDAH APPROVE
A43: 04 Mei | C43: Syahrudin | D43: Tempe Bakung 2 | F43: 90 | G43: 12000 | I43: =G43*F43 -> 1080000 | J43: =I43 -> 1080000 | K43: SUDAH APPROVE
...

Sheet Kas Besar
A1: LAPORAN BELANJA BAHAN BAKU
A2: KOPERASI GOTONG ROYONG SEJAHTERA NUSANTARA
A3: MEI 2026
A5: TANGGAL | B5: PENERIMA | C5: TOTAL | D5: ITEM | E5: QTY | F5: SATUAN | G5: HARGA SATUAN | H5: TOTAL | I5: KETERANGAN
A6: 01 JUNI 2026 | H6: =SUM(H7) -> 2000000
B7: LISMA | D7: PETTY CASH | E7: 1 | G7: 2000000 | H7: =E7*G7 -> 2000000
A8: 02 JUNI 2026 | H8: =SUM(H9) -> 500000
B9: LISMA | D9: TOKEN LISTRIK | E9: 1 | G9: 500000 | H9: =G9 -> 500000
A10: 05 JUNI 2026 | H10: =SUM(H11:H16) -> 36700000
B11: BAMBANG SETIAWAN | D11: PENGAJUAN BIAYA SEWA MOBIL SPPG 24 MEI-6 JUNI 2026 | E11: 3 | F11: UNIT | G11: 2700000 | H11: =G11*E11 -> 8100000
E12: 8 | F12: UNIT | G12: 2400000 | H12: =G12*E12 -> 19200000
E13: 1 | F13: UNIT | G13: 2000000 | H13: =G13*E13 -> 2000000
D14: PENGAJUAN BIATA KOORDINASI WILAYAH | E14: 1 | G14: 3000000 | H14: =G14*E14 -> 3000000
D15: PENGAJUAN BIAYA SEWA MOBIL OPRASIONAL KOPRASI 24 MEI- 6 JUNI 2026 | E15: 1 | F15: UNIT | G15: 2400000 | H15: =G15*E15 -> 2400000
E16: 1 | F16: UNIT | G16: 2000000 | H16: =G16*E16 -> 2000000
A17: 16 JUNI 2026 | H17: =SUM(H18:H23) -> 67500000
B18: LISMA | D18: PETTYCASH | E18: 1 | G18: 1000000 | H18: =G18 -> 1000000
D19: TOKEN LISTRIK | E19: 1 | G19: 500000 | H19: =G19 -> 500000
A20: 19 JUNI 2026 | H20: =SUM(H21:H26) -> 36700000
B21: BAMBANG SETIAWAN | D21: PENGAJUAN BIAYA SEWA MOBIL SPPG 7-20 JUNI 2026 | E21: 3 | F21: UNIT | G21: 2700000 | H21: =G21*E21 -> 8100000
E22: 8 | F22: UNIT | G22: 2400000 | H22: =G22*E22 -> 19200000
E23: 1 | F23: UNIT | G23: 2000000 | H23: =G23*E23 -> 2000000
D24: PENGAJUAN BIATA KOORDINASI WILAYAH 7-20 JUNI 2026 | E24: 1 | G24: 3000000 | H24: =G24*E24 -> 3000000
D25: PENGAJUAN BIAYA SEWA MOBIL OPRASIONAL KOPRASI 7- 20 JUNI 2026 | E25: 1 | F25: UNIT | G25: 2400000 | H25: =G25*E25 -> 2400000
E26: 1 | F26: UNIT | G26: 2000000 | H26: =G26*E26 -> 2000000
E27: 3 | G27: 2500 | H27: =E27*G27 -> 7500 | I27: =H27 -> 7500
A28: JUNI 2026 | H28: =SUM(H29:H34) -> 0

Sheet Daftar Harga
A1: 💰 DAFTAR HARGA REFERENSI (Sumber: Rekap Mei 2026) — BISA DIEDIT
A2: ⚠️ Harga BIRU = input manual. Ubah di sini → otomatis update semua invoice.
A3: No | B3: Nama Barang | C3: Satuan | D3: Harga Beli (Rp) | E3: Harga Jual (Rp) | F3: Margin (Rp) | G3: Margin (%)
A4: 1 | B4: Anggur | C4: Kg | D4: 90000 | E4: 92000 | F4: =IF(AND(D4<>"",E4<>""),E4-D4,"") -> 2000 | G4: =IF(AND(D4<>"",E4<>"",D4<>0),(E4-D4)/D4,"") -> 0.022222222
A5: 2 | B5: Apel | C5: Pcs | D5: 26000 | E5: 30000 | F5: =IF(AND(D5<>"",E5<>""),E5-D5,"") -> 4000 | G5: =IF(AND(D5<>"",E5<>"",D5<>0),(E5-D5)/D5,"") -> 0.15384615
A6: 3 | B6: Asam Jawa | C6: Kg | F6: =IF(AND(D6<>"",E6<>""),E6-D6,"") | G6: =IF(AND(D6<>"",E6<>"",D6<>0),(E6-D6)/D6,"")
A7: 4 | B7: Ayam Dada Fillet | C7: Kg | D7: 46500 | E7: 52000 | F7: =IF(AND(D7<>"",E7<>""),E7-D7,"") -> 5500 | G7: =IF(AND(D7<>"",E7<>"",D7<>0),(E7-D7)/D7,"") -> 0.11827957
A8: 5 | B8: Ayam Fillet | C8: Kg | D8: 48000 | E8: 54000 | F8: =IF(AND(D8<>"",E8<>""),E8-D8,"") -> 6000 | G8: =IF(AND(D8<>"",E8<>"",D8<>0),(E8-D8)/D8,"") -> 0.125
A9: 6 | B9: Ayam Potong | C9: Kg | D9: 36500 | E9: 38000 | F9: =IF(AND(D9<>"",E9<>""),E9-D9,"") -> 1500 | G9: =IF(AND(D9<>"",E9<>"",D9<>0),(E9-D9)/D9,"") -> 0.04109589
A10: 7 | B10: Ayam Potong Sayap | C10: Kg | D10: 36500 | E10: 38000 | F10: =IF(AND(D10<>"",E10<>""),E10-D10,"") -> 1500 | G10: =IF(AND(D10<>"",E10<>"",D10<>0),(E10-D10)/D10,"") -> 0.04109589
A11: 8 | B11: Bandeng presto | C11: Pcs | F11: =IF(AND(D11<>"",E11<>""),E11-D11,"") | G11: =IF(AND(D11<>"",E11<>"",D11<>0),(E11-D11)/D11,"")
A12: 9 | B12: Bawang Bombay | C12: Kg | D12: 30000 | E12: 40000 | F12: =IF(AND(D12<>"",E12<>""),E12-D12,"") -> 10000 | G12: =IF(AND(D12<>"",E12<>"",D12<>0),(E12-D12)/D12,"") -> 0.33333333
A13: 10 | B13: Bawang merah | C13: Kg | D13: 28000 | E13: 30000 | F13: =IF(AND(D13<>"",E13<>""),E13-D13,"") -> 2000 | G13: =IF(AND(D13<>"",E13<>"",D13<>0),(E13-D13)/D13,"") -> 0.071428571
A14: 11 | B14: Bawang merah kupas | C14: Kg | D14: 40000 | E14: 45000 | F14: =IF(AND(D14<>"",E14<>""),E14-D14,"") -> 5000 | G14: =IF(AND(D14<>"",E14<>"",D14<>0),(E14-D14)/D14,"") -> 0.125
A15: 12 | B15: Bawang putih | C15: Kg | D15: 33000 | E15: 36000 | F15: =IF(AND(D15<>"",E15<>""),E15-D15,"") -> 3000 | G15: =IF(AND(D15<>"",E15<>"",D15<>0),(E15-D15)/D15,"") -> 0.090909091
A16: 13 | B16: Bawang putih kupas | C16: Kg | D16: 33000 | E16: 45000 | F16: =IF(AND(D16<>"",E16<>""),E16-D16,"") -> 12000 | G16: =IF(AND(D16<>"",E16<>"",D16<>0),(E16-D16)/D16,"") -> 0.36363636
A17: 14 | B17: Beras | C17: Kg | D17: 15500 | E17: 15500 | F17: =IF(AND(D17<>"",E17<>""),E17-D17,"") -> 0 | G17: =IF(AND(D17<>"",E17<>"",D17<>0),(E17-D17)/D17,"") -> 0
A18: 15 | B18: Blimbing | C18: Kg | F18: =IF(AND(D18<>"",E18<>""),E18-D18,"") | G18: =IF(AND(D18<>"",E18<>"",D18<>0),(E18-D18)/D18,"")
A19: 16 | B19: Buah pir | C19: Pcs | D19: 22500 | E19: 23500 | F19: =IF(AND(D19<>"",E19<>""),E19-D19,"") -> 1000 | G19: =IF(AND(D19<>"",E19<>"",D19<>0),(E19-D19)/D19,"") -> 0.044444444
A20: 17 | B20: Buah Plum | C20: Dus | D20: 22500 | E20: 23500 | F20: =IF(AND(D20<>"",E20<>""),E20-D20,"") -> 1000 | G20: =IF(AND(D20<>"",E20<>"",D20<>0),(E20-D20)/D20,"") -> 0.044444444
A21: 18 | B21: Bubuk Gochugaru | C21: Kg | D21: 170000 | E21: 180000 | F21: =IF(AND(D21<>"",E21<>""),E21-D21,"") -> 10000 | G21: =IF(AND(D21<>"",E21<>"",D21<>0),(E21-D21)/D21,"") -> 0.058823529
A22: 19 | B22: Bubuk Ngohiong | C22: Kg | D22: 170000 | E22: 180000 | F22: =IF(AND(D22<>"",E22<>""),E22-D22,"") -> 10000 | G22: =IF(AND(D22<>"",E22<>"",D22<>0),(E22-D22)/D22,"") -> 0.058823529
A23: 20 | B23: Bubuk Paprika | C23: Kg | D23: 170000 | E23: 180000 | F23: =IF(AND(D23<>"",E23<>""),E23-D23,"") -> 10000 | G23: =IF(AND(D23<>"",E23<>"",D23<>0),(E23-D23)/D23,"") -> 0.058823529
A24: 21 | B24: Buncis | C24: Kg | D24: 13000 | E24: 16000 | F24: =IF(AND(D24<>"",E24<>""),E24-D24,"") -> 3000 | G24: =IF(AND(D24<>"",E24<>"",D24<>0),(E24-D24)/D24,"") -> 0.23076923
A25: 22 | B25: Cabai merah | C25: Kg | D25: 47000 | E25: 52000 | F25: =IF(AND(D25<>"",E25<>""),E25-D25,"") -> 5000 | G25: =IF(AND(D25<>"",E25<>"",D25<>0),(E25-D25)/D25,"") -> 0.10638298
A26: 23 | B26: Cabai merah besar | C26: Kg | D26: 47000 | E26: 52000 | F26: =IF(AND(D26<>"",E26<>""),E26-D26,"") -> 5000 | G26: =IF(AND(D26<>"",E26<>"",D26<>0),(E26-D26)/D26,"") -> 0.10638298
A27: 24 | B27: Cabai rawit merah | C27: Kg | D27: 80000 | E27: 90000 | F27: =IF(AND(D27<>"",E27<>""),E27-D27,"") -> 10000 | G27: =IF(AND(D27<>"",E27<>"",D27<>0),(E27-D27)/D27,"") -> 0.125
A28: 25 | B28: Daging Ayam Giling | C28: Kg | D28: 52000 | E28: 65000 | F28: =IF(AND(D28<>"",E28<>""),E28-D28,"") -> 13000 | G28: =IF(AND(D28<>"",E28<>"",D28<>0),(E28-D28)/D28,"") -> 0.25
A29: 26 | B29: Daun bawang | C29: Kg | D29: 10000 | E29: 12000 | F29: =IF(AND(D29<>"",E29<>""),E29-D29,"") -> 2000 | G29: =IF(AND(D29<>"",E29<>"",D29<>0),(E29-D29)/D29,"") -> 0.2
A30: 27 | B30: Daun jeruk | C30: Kg | D30: 27000 | E30: 35000 | F30: =IF(AND(D30<>"",E30<>""),E30-D30,"") -> 8000 | G30: =IF(AND(D30<>"",E30<>"",D30<>0),(E30-D30)/D30,"") -> 0.2962963
... A32: 29 | B32: Daun Salam | C32: Kg | D32: 21600 | E32: 15000 | F32: =IF(AND(D32<>"",E32<>""),E32-D32,"") -> -6600 | G32: =IF(AND(D32<>"",E32<>"",D32<>0),(E32-D32)/D32,"") -> -0.30555556
A33: 30 | B33: Edamame | C33: Kg | F33: =IF(AND(D33<>"",E33<>""),E33-D33,"") | G33: =IF(AND(D33<>"",E33<>"",D33<>0),(E33-D33)/D33,"")
A34: 31 | B34: Garam | C34: Kg | D34: 9000 | E34: 10500 | F34: =IF(AND(D34<>"",E34<>""),E34-D34,"") -> 1500 | G34: =IF(AND(D34<>"",E34<>"",D34<>0),(E34-D34)/D34,"") -> 0.16666667
A35: 32 | B35: Gula merah | C35: Kg | D35: 17000 | E35: 22000 | F35: =IF(AND(D35<>"",E35<>""),E35-D35,"") -> 5000 | G35: =IF(AND(D35<>"",E35<>"",D35<>0),(E35-D35)/D35,"") -> 0.29411765
A36: 33 | B36: Gula pasir | C36: Kg | D36: 19000 | E36: 20000 | F36: =IF(AND(D36<>"",E36<>""),E36-D36,"") -> 1000 | G36: =IF(AND(D36<>"",E36<>"",D36<>0),(E36-D36)/D36,"") -> 0.052631579
A37: 34 | B37: Ikan Tongkol | C37: Kg | D37: 6500 | E37: 14000 | F37: =IF(AND(D37<>"",E37<>""),E37-D37,"") -> 7500 | G37: =IF(AND(D37<>"",E37<>"",D37<>0),(E37-D37)/D37,"") -> 1.1538462
A38: 35 | B38: Jagung pipil | C38: Kg | D38: 24000 | E38: 24000 | F38: =IF(AND(D38<>"",E38<>""),E38-D38,"") -> 0 | G38: =IF(AND(D38<>"",E38<>"",D38<>0),(E38-D38)/D38,"") -> 0
A39: 36 | B39: Jahe | C39: Kg | D39: 20000 | E39: 260000 | F39: =IF(AND(D39<>"",E39<>""),E39-D39,"") -> 240000 | G39: =IF(AND(D39<>"",E39<>"",D39<>0),(E39-D39)/D39,"") -> 12
A40: 37 | B40: Jeruk | C40: Pcs | D40: 29000 | E40: 32000 | F40: =IF(AND(D40<>"",E40<>""),E40-D40,"") -> 3000 | G40: =IF(AND(D40<>"",E40<>"",D40<>0),(E40-D40)/D40,"") -> 0.10344828
A41: 38 | B41: Jeruk Limau | C41: Kg | D41: 29000 | E41: 32000 | F41: =IF(AND(D41<>"",E41<>""),E41-D41,"") -> 3000 | G41: =IF(AND(D41<>"",E41<>"",D41<>0),(E41-D41)/D41,"") -> 0.10344828
...

Sheet Invoice B01
A1: 🧾 DRAFT INVOICE — BAKUNG 01
A2: Periode: Mei-Juni 2026 | 🟢 Hijau = linked Daftar Harga | 🔵 Biru = input manual (isi setelah nota datang)
A3: Kolom G (Harga Beli Nota) dikosongkan — isi saat barang tiba. Margin: pakai Nota jika ada, fallback ke Estimasi.
A4: 📅 Sunday, 24 May 2026
A5: No | B5: Nama Barang | C5: Satuan | D5: Qty | E5: 📊 ESTIMASI | G5: 🧾 REALISASI BELI | I5: 💰 PENJUALAN | K5: 📈 MARGIN | M5: Keterangan
A6: No | B6: Nama Barang | C6: Satuan | D6: Qty | E6: Est. Harga Beli (Rp) | F6: Total Estimasi (Rp) | G6: Harga Beli Nota (Rp) | H6: Total Beli Nota (Rp) | I6: Harga Jual (Rp) | J6: Total Jual (Rp) | K6: Margin (Rp) | L6: Margin (%) | M6: Keterangan
A7: 1 | B7: Bandeng presto | C7: Pcs | D7: 2550 | E7: ='Daftar Harga'!D11 | F7: =IF(E7<>"",D7*E7,"") | G7: 3500 | H7: =IF(G7<>"",D7*G7,"") -> 8925000 | I7: 3800 | J7: =IF(I7<>"",D7*I7,"") -> 9690000 | K7: =IF(J7<>"",IF(H7<>"",J7-H7,IF(F7<>"",J7-F7,"")),"") -> 765000 | L7: =IF(K7<>"",IF(H7<>"",IF(H7<>0,K7/H7,""),IF(F7<>"",IF(F7<>0,K7/F7,""),"")),"") -> 0.085714286
A8: 2 | B8: Bawang merah kupas | C8: Kg | D8: 3 | E8: ='Daftar Harga'!D14 -> 40000 | F8: =IF(E8<>"",D8*E8,"") -> 120000 | G8: 40000 | H8: =IF(G8<>"",D8*G8,"") -> 120000 | I8: 45000 | J8: =IF(I8<>"",D8*I8,"") -> 135000 | K8: =IF(J8<>"",IF(H8<>"",J8-H8,IF(F8<>"",J8-F8,"")),"") -> 15000 | L8: =IF(K8<>"",IF(H8<>"",IF(H8<>0,K8/H8,""),IF(F8<>"",IF(F8<>0,K8/F8,""),"")),"") -> 0.125
A9: 3 | B9: Bawang putih kupas | C9: Kg | D9: 3 | E9: ='Daftar Harga'!D16 -> 33000 | F9: =IF(E9<>"",D9*E9,"") -> 99000 | G9: 30000 | H9: =IF(G9<>"",D9*G9,"") -> 90000 | I9: 44000 | J9: =IF(I9<>"",D9*I9,"") -> 132000 | K9: =IF(J9<>"",IF(H9<>"",J9-H9,IF(F9<>"",J9-F9,"")),"") -> 42000 | L9: =IF(K9<>"",IF(H9<>"",IF(H9<>0,K9/H9,""),IF(F9<>"",IF(F9<>0,K9/F9,""),"")),"") -> 0.46666667
A10: 4 | B10: Beras | C10: Kg | D10: 100 | E10: ='Daftar Harga'!D17 -> 15500 | F10: =IF(E10<>"",D10*E10,"") -> 1550000 | G10: 14500 | H10: =IF(G10<>"",D10*G10,"") -> 1450000 | I10: 15500 | J10: =IF(I10<>"",D10*I10,"") -> 1550000 | K10: =IF(J10<>"",IF(H10<>"",J10-H10,IF(F10<>"",J10-F10,"")),"") -> 100000 | L10: =IF(K10<>"",IF(H10<>"",IF(H10<>0,K10/H10,""),IF(F10<>"",IF(F10<>0,K10/F10,""),"")),"") -> 0.068965517
A11: 5 | B11: Gula pasir | C11: Kg | D11: 5 | E11: ='Daftar Harga'!D36 -> 19000 | F11: =IF(E11<>"",D11*E11,"") -> 95000 | G11: 18500 | H11: =IF(G11<>"",D11*G11,"") -> 92500 | I11: 20000 | J11: =IF(I11<>"",D11*I11,"") -> 100000 | K11: =IF(J11<>"",IF(H11<>"",J11-H11,IF(F11<>"",J11-F11,"")),"") -> 7500 | L11: =IF(K11<>"",IF(H11<>"",IF(H11<>0,K11/H11,""),IF(F11<>"",IF(F11<>0,K11/F11,""),"")),"") -> 0.081081081
A12: 6 | B12: Knorr | C12: Kg | D12: 5 | E12: ='Daftar Harga'!D57 -> 95000 | F12: =IF(E12<>"",D12*E12,"") -> 475000 | G12: 94000 | H12: =IF(G12<>"",D12*G12,"") -> 470000 | I12: 105000 | J12: =IF(I12<>"",D12*I12,"") -> 525000 | K12: =IF(J12<>"",IF(H12<>"",J12-H12,IF(F12<>"",J12-F12,"")),"") -> 55000 | L12: =IF(K12<>"",IF(H12<>"",IF(H12<>0,K12/H12,""),IF(F12<>"",IF(F12<>0,K12/F12,""),"")),"") -> 0.11702128
A13: 7 | B13: Kol | C13: Kg | D13: 60 | E13: ='Daftar Harga'!D58 -> 6500 | F13: =IF(E13<>"",D13*E13,"") -> 390000 | G13: 7500 | H13: =IF(G13<>"",D13*G13,"") -> 450000 | I13: 12000 | J13: =IF(I13<>"",D13*I13,"") -> 720000 | K13: =IF(J13<>"",IF(H13<>"",J13-H13,IF(F13<>"",J13-F13,"")),"") -> 270000 | L13: =IF(K13<>"",IF(H13<>"",IF(H13<>0,K13/H13,""),IF(F13<>"",IF(F13<>0,K13/F13,""),"")),"") -> 0.6
A14: 8 | B14: Kunyit | C14: Kg | D14: 1 | E14: ='Daftar Harga'!D60 -> 12000 | F14: =IF(E14<>"",D14*E14,"") -> 12000 | G14: 12000 | H14: =IF(G14<>"",D14*G14,"") -> 12000 | I14: 16000 | J14: =IF(I14<>"",D14*I14,"") -> 16000 | K14: =IF(J14<>"",IF(H14<>"",J14-H14,IF(F14<>"",J14-F14,"")),"") -> 4000 | L14: =IF(K14<>"",IF(H14<>"",IF(H14<>0,K14/H14,""),IF(F14<>"",IF(F14<>0,K14/F14,""),"")),"") -> 0.33333333
A15: 9 | B15: Minyak | C15: Liter | D15: 60 | E15: ='Daftar Harga'!D69 -> 205000 | F15: =IF(E15<>"",D15*E15,"") -> 12300000 | G15: 22000 | H15: =IF(G15<>"",D15*G15,"") -> 1320000 | I15: 23000 | J15: =IF(I15<>"",D15*I15,"") -> 1380000 | K15: =IF(J15<>"",IF(H15<>"",J15-H15,IF(F15<>"",J15-F15,"")),"") -> 60000 | L15: =IF(K15<>"",IF(H15<>"",IF(H15<>0,K15/H15,""),IF(F15<>"",IF(F15<>0,K15/F15,""),"")),"") -> 0.045454545
A16: 10 | B16: Tahu | C16: Pcs | D16: 2600 | E16: ='Daftar Harga'!D71 -> 1900 | F16: =IF(E16<>"",D16*E16,"") -> 4940000 | G16: 480 | H16: =IF(G16<>"",D16*G16,"") -> 1248000 | I16: 700 | J16: =IF(I16<>"",D16*I16,"") -> 1820000 | K16: =IF(J16<>"",IF(H16<>"",J16-H16,IF(F16<>"",J16-F16,"")),"") -> 572000 | L16: =IF(K16<>"",IF(H16<>"",IF(H16<>0,K16/H16,""),IF(F16<>"",IF(F16<>0,K16/F16,""),"")),"") -> 0.45833333
A17: 11 | B17: Sawi hijau | C17: Kg | D17: 20 | E17: ='Daftar Harga'!D82 -> 9000 | F17: =IF(E17<>"",D17*E17,"") -> 180000 | G17: 6000 | H17: =IF(G17<>"",D17*G17,"") -> 120000 | I17: 12000 | J17: =IF(I17<>"",D17*I17,"") -> 240000 | K17: =IF(J17<>"",IF(H17<>"",J17-H17,IF(F17<>"",J17-F17,"")),"") -> 120000 | L17: =IF(K17<>"",IF(H17<>"",IF(H17<>0,K17/H17,""),IF(F17<>"",IF(F17<>0,K17/F17,""),"")),"") -> 1
A18: 12 | B18: Wortel | C18: Kg | D18: 30 | E18: ='Daftar Harga'!D101 -> 9000 | F18: =IF(E18<>"",D18*E18,"") -> 270000 | G18: 12000 | H18: =IF(G18<>"",D18*G18,"") -> 360000 | I18: 14000 | J18: =IF(I18<>"",D18*I18,"") -> 420000 | K18: =IF(J18<>"",IF(H18<>"",J18-H18,IF(F18<>"",J18-F18,"")),"") -> 60000 | L18: =IF(K18<>"",IF(H18<>"",IF(H18<>0,K18/H18,""),IF(F18<>"",IF(F18<>0,K18/F18,""),"")),"") -> 0.16666667
A19: 13 | B19: Semangka | C19: Kg | D19: 220 | E19: ='Daftar Harga'!D102 | F19: =IF(E19<>"",D19*E19,"") | G19: 18500 | H19: =IF(G19<>"",D19*G19,"") -> 4070000 | I19: 20500 | J19: =IF(I19<>"",D19*I19,"") -> 4510000 | K19: =IF(J19<>"",IF(H19<>"",J19-H19,IF(F19<>"",J19-F19,"")),"") -> 440000 | L19: =IF(K19<>"",IF(H19<>"",IF(H19<>0,K19/H19,""),IF(F19<>"",IF(F19<>0,K19/F19,""),"")),"") -> 0.10810811
A20: 14 | B20: Apel | C20: Box | D20: 7 | E20: ='Daftar Harga'!D103 | F20: =IF(E20<>"",D20*E20,"") | G20: 590000 | H20: =IF(G20<>"",D20*G20,"") -> 4130000 | I20: 605000 | J20: =IF(I20<>"",D20*I20,"") -> 4235000 | K20: =IF(J20<>"",IF(H20<>"",J20-H20,IF(F20<>"",J20-F20,"")),"") -> 105000 | L20: =IF(K20<>"",IF(H20<>"",IF(H20<>0,K20/H20,""),IF(F20<>"",IF(F20<>0,K20/F20,""),"")),"") -> 0.025423729
A21: SUBTOTAL 24 May 2026 | F21: =SUMIF(F7:F20,"<>",F7:F20) -> 20431000 | H21: =SUMIF(H7:H20,"<>",H7:H20) -> 22857500 | J21: =SUMIF(J7:J20,"<>",J7:J20) -> 25473000 | K21: =IF(J21<>"",IF(H21<>"",J21-H21,IF(F21<>"",J21-F21,"")),"") -> 2615500 | L21: =IF(K21<>"",IF(H21<>"",IF(H21<>0,K21/H21,""),IF(F21<>"",IF(F21<>0,K21/F21,""),"")),"") -> 0.11442634
A23: 📅 Monday, 25 May 2026
A24: No | B24: Nama Barang | C24: Satuan | D24: Qty | E24: 📊 ESTIMASI | G24: 🧾 REALISASI BELI | I24: 💰 PENJUALAN | K24: 📈 MARGIN | M24: Keterangan
A25: No | B25: Nama Barang | C25: Satuan | D25: Qty | E25: Est. Harga Beli (Rp) | F25: Total Estimasi (Rp) | G25: Harga Beli Nota (Rp) | H25: Total Beli Nota (Rp) | I25: Harga Jual (Rp) | J25: Total Jual (Rp) | K25: Margin (Rp) | L25: Margin (%) | M25: Keterangan
A26: 1 | B26: Ayam Potong | C26: Kg | D26: 265 | E26: ='Daftar Harga'!D9 -> 36500 | F26: =IF(E26<>"",D26*E26,"") -> 9672500 | G26: 34000 | H26: =IF(G26<>"",D26*G26,"") -> 9010000 | I26: 38000 | J26: =IF(I26<>"",D26*I26,"") -> 10070000 | K26: =IF(J26<>"",IF(H26<>"",J26-H26,IF(F26<>"",J26-F26,"")),"") -> 1060000 | L26: =IF(K26<>"",IF(H26<>"",IF(H26<>0,K26/H26,""),IF(F26<>"",IF(F26<>0,K26/F26,""),"")),"") -> 0.11764706
A27: 2 | B27: Bawang merah kupas | C27: Kg | D27: 3 | E27: ='Daftar Harga'!D14 -> 40000 | F27: =IF(E27<>"",D27*E27,"") -> 120000 | G27: 40000 | H27: =IF(G27<>"",D27*G27,"") -> 120000 | I27: 45000 | J27: =IF(I27<>"",D27*I27,"") -> 135000 | K27: =IF(J27<>"",IF(H27<>"",J27-H27,IF(F27<>"",J27-F27,"")),"") -> 15000 | L27: =IF(K27<>"",IF(H27<>"",IF(H27<>0,K27/H27,""),IF(F27<>"",IF(F27<>0,K27/F27,""),"")),"") -> 0.125
A28: 3 | B28: Bawang putih kupas | C28: Kg | D28: 3 | E28: ='Daftar Harga'!D16 -> 33000 | F28: =IF(E28<>"",D28*E28,"") -> 99000 | G28: 30000 | H28: =IF(G28<>"",D28*G28,"") -> 90000 | I28: 40000 | J28: =IF(I28<>"",D28*I28,"") -> 120000 | K28: =IF(J28<>"",IF(H28<>"",J28-H28,IF(F28<>"",J28-F28,"")),"") -> 30000 | L28: =IF(K28<>"",IF(H28<>"",IF(H28<>0,K28/H28,""),IF(F28<>"",IF(F28<>0,K28/F28,""),"")),"") -> 0.33333333
A29: 4 | B29: Beras | C29: Kg | D29: 125 | E29: ='Daftar Harga'!D17 -> 15500 | F29: =IF(E29<>"",D29*E29,"") -> 1937500 | G29: 14500 | H29: =IF(G29<>"",D29*G29,"") -> 1812500 | I29: 15500 | J29: =IF(I29<>"",D29*I29,"") -> 1937500 | K29: =IF(J29<>"",IF(H29<>"",J29-H29,IF(F29<>"",J29-F29,"")),"") -> 125000 | L29: =IF(K29<>"",IF(H29<>"",IF(H29<>0,K29/H29,""),IF(F29<>"",IF(F29<>0,K29/F29,""),"")),"") -> 0.068965517
A30: 5 | B30: Blimbing | C30: Kg | D30: 67 | E30: ='Daftar Harga'!D18 | F30: =IF(E30<>"",D30*E30,"") | G30: 15000 | H30: =IF(G30<>"",D30*G30,"") -> 1005000 | I30: 20000 | J30: =IF(I30<>"",D30*I30,"") -> 1340000 | K30: =IF(J30<>"",IF(H30<>"",J30-H30,IF(F30<>"",J30-F30,"")),"") -> 335000 | L30: =IF(K30<>"",IF(H30<>"",IF(H30<>0,K30/H30,""),IF(F30<>"",IF(F30<>0,K30/F30,""),"")),"") -> 0.33333333
A31: 6 | B31: Gula pasir | C31: Kg | D31: 10 | E31: ='Daftar Harga'!D36 -> 19000 | F31: =IF(E31<>"",D31*E31,"") -> 190000 | G31: 18500 | H31: =IF(G31<>"",D31*G31,"") -> 185000 | I31: 20000 | J31: =IF(I31<>"",D31*I31,"") -> 200000 | K31: =IF(J31<>"",IF(H31<>"",J31-H31,IF(F31<>"",J31-F31,"")),"") -> 15000 | L31: =IF(K31<>"",IF(H31<>"",IF(H31<>0,K31/H31,""),IF(F31<>"",IF(F31<>0,K31/F31,""),"")),"") -> 0.081081081
A32: 7 | B32: Knorr | C32: Kg | D32: 2 | E32: ='Daftar Harga'!D57 -> 95000 | F32: =IF(E32<>"",D32*E32,"") -> 190000 | G32: 94500 | H32: =IF(G32<>"",D32*G32,"") -> 189000 | I32: 110000 | J32: =IF(I32<>"",D32*I32,"") -> 220000 | K32: =IF(J32<>"",IF(H32<>"",J32-H32,IF(F32<>"",J32-F32,"")),"") -> 31000 | L32: =IF(K32<>"",IF(H32<>"",IF(H32<>0,K32/H32,""),IF(F32<>"",IF(F32<>0,K32/F32,""),"")),"") -> 0.16402116
A33: 8 | B33: Kunyit | C33: Kg | D33: 2 | E33: ='Daftar Harga'!D60 -> 12000 | F33: =IF(E33<>"",D33*E33,"") -> 24000 | G33: 11667 | H33: =IF(G33<>"",D33*G33,"") -> 23334 | I33: 15000 | J33: =IF(I33<>"",D33*I33,"") -> 30000 | K33: =IF(J33<>"",IF(H33<>"",J33-H33,IF(F33<>"",J33-F33,"")),"") -> 6666 | L33: =IF(K33<>"",IF(H33<>"",IF(H33<>0,K33/H33,""),IF(F33<>"",IF(F33<>0,K33/F33,""),"")),"") -> 0.28567755
A34: 9 | B34: Minyak | C34: Liter | D34: 50 | E34: ='Daftar Harga'!D69 -> 205000 | F34: =IF(E34<>"",D34*E34,"") -> 10250000 | G34: 22000 | H34: =IF(G34<>"",D34*G34,"") -> 1100000 | I34: 25000 | J34: =IF(I34<>"",D34*I34,"") -> 1250000 | K34: =IF(J34<>"",IF(H34<>"",J34-H34,IF(F34<>"",J34-F34,"")),"") -> 150000 | L34: =IF(K34<>"",IF(H34<>"",IF(H34<>0,K34/H34,""),IF(F34<>"",IF(F34<>0,K34/F34,""),"")),"") -> 0.13636364
A35: 10 | B35: Semangka | C35: Kg | D35: 230 | E35: ='Daftar Harga'!D85 -> 18500 | F35: =IF(E35<>"",D35*E35,"") -> 4255000 | G35: 18500 | H35: =IF(G35<>"",D35*G35,"") -> 4255000 | I35: 21500 | J35: =IF(I35<>"",D35*I35,"") -> 4945000 | K35: =IF(J35<>"",IF(H35<>"",J35-H35,IF(F35<>"",J35-F35,"")),"") -> 690000 | L35: =IF(K35<>"",IF(H35<>"",IF(H35<>0,K35/H35,""),IF(F35<>"",IF(F35<>0,K35/F35,""),"")),"") -> 0.16216216
A36: 11 | B36: Tempe | C36: Papan | D36: 130 | E36: ='Daftar Harga'!D93 -> 12000 | F36: =IF(E36<>"",D36*E36,"") -> 1560000 | G36: 12000 | H36: =IF(G36<>"",D36*G36,"") -> 1560000 | I36: 14000 | J36: =IF(I36<>"",D36*I36,"") -> 1820000 | K36: =IF(J36<>"",IF(H36<>"",J36-H36,IF(F36<>"",J36-F36,"")),"") -> 260000 | L36: =IF(K36<>"",IF(H36<>"",IF(H36<>0,K36/H36,""),IF(F36<>"",IF(F36<>0,K36/F36,""),"")),"") -> 0.16666667
A37: 12 | B37: Tepung Serbaguna | C37: Kg | D37: 30 | E37: ='Daftar Harga'!D95 -> 23000 | F37: =IF(E37<>"",D37*E37,"") -> 690000 | G37: 22500 | H37: =IF(G37<>"",D37*G37,"") -> 675000 | I37: 26500 | J37: =IF(I37<>"",D37*I37,"") -> 795000 | K37: =IF(J37<>"",IF(H37<>"",J37-H37,IF(F37<>"",J37-F37,"")),"") -> 120000 | L37: =IF(K37<>"",IF(H37<>"",IF(H37<>0,K37/H37,""),IF(F37<>"",IF(F37<>0,K37/F37,""),"")),"") -> 0.17777778
A38: 13 | B38: Timun | C38: Kg | D38: 90 | E38: ='Daftar Harga'!D99 -> 8000 | F38: =IF(E38<>"",D38*E38,"") -> 720000 | G38: 9000 | H38: =IF(G38<>"",D38*G38,"") -> 810000 | I38: 13000 | J38: =IF(I38<>"",D38*I38,"") -> 1170000 | K38: =IF(J38<>"",IF(H38<>"",J38-H38,IF(F38<>"",J38-F38,"")),"") -> 360000 | L38: =IF(K38<>"",IF(H38<>"",IF(H38<>0,K38/H38,""),IF(F38<>"",IF(F38<>0,K38/F38,""),"")),"") -> 0.44444444
A39: 14 | B39: Wortel | C39: Kg | D39: 30 | E39: ='Daftar Harga'!D101 -> 9000 | F39: =IF(E39<>"",D39*E39,"") -> 270000 | G39: 12000 | H39: =IF(G39<>"",D39*G39,"") -> 360000 | I39: 14000 | J39: =IF(I39<>"",D39*I39,"") -> 420000 | K39: =IF(J39<>"",IF(H39<>"",J39-H39,IF(F39<>"",J39-F39,"")),"") -> 60000 | L39: =IF(K39<>"",IF(H39<>"",IF(H39<>0,K39/H39,""),IF(F39<>"",IF(F39<>0,K39/F39,""),"")),"") -> 0.16666667
A40: 15 | B40: Kecap Sedap 720Ml | C40: Pcs | D40: 4 | F40: =IF(E40<>"",D40*E40,"") | G40: 26900 | H40: =IF(G40<>"",D40*G40,"") -> 107600 | I40: 30000 | J40: =IF(I40<>"",D40*I40,"") -> 120000 | K40: =IF(J40<>"",IF(H40<>"",J40-H40,IF(F40<>"",J40-F40,"")),"") -> 12400 | L40: =IF(K40<>"",IF(H40<>"",IF(H40<>0,K40/H40,""),IF(F40<>"",IF(F40<>0,K40/F40,""),"")),"") -> 0.11524164
A41: 16 | B41: Kecap Bango 700 Gr | C41: Pcs | D41: 3 | F41: =IF(E41<>"",D41*E41,"") | G41: 26900 | H41: =IF(G41<>"",D41*G41,"") -> 80700 | I41: 30000 | J41: =IF(I41<>"",D41*I41,"") -> 90000 | K41: =IF(J41<>"",IF(H41<>"",J41-H41,IF(F41<>"",J41-F41,"")),"") -> 9300 | L41: =IF(K41<>"",IF(H41<>"",IF(H41<>0,K41/H41,""),IF(F41<>"",IF(F41<>0,K41/F41,""),"")),"") -> 0.11524164
...

Sheet Invoice OPS B01
A1: 🧾 DRAFT INVOICE — BAKUNG 01
A2: Periode: Mei-Juni 2026 | 🟢 Hijau = linked Daftar Harga | 🔵 Biru = input manual (isi setelah nota datang)
A3: Kolom G (Harga Beli Nota) dikosongkan — isi saat barang tiba. Margin: pakai Nota jika ada, fallback ke Estimasi.
A4: 📅 Sunday, 24 May 2026
A5: No | B5: Nama Barang | C5: Satuan | D5: Qty | E5: 📊 ESTIMASI | G5: 🧾 REALISASI BELI | I5: 💰 PENJUALAN | K5: 📈 MARGIN | M5: Keterangan
A6: No | B6: Nama Barang | C6: Satuan | D6: Qty | E6: Est. Harga Beli (Rp) | F6: Total Estimasi (Rp) | G6: Harga Beli Nota (Rp) | H6: Total Beli Nota (Rp) | I6: Harga Jual (Rp) | J6: Total Jual (Rp) | K6: Margin (Rp) | L6: Margin (%) | M6: Keterangan
A7: 1 | B7: Sarung Tangan Finnil | C7: Pack | D7: 10 | F7: =IF(E7<>"",D7*E7,"") | G7: 65000 | H7: =IF(G7<>"",D7*G7,"") -> 650000 | I7: 75000 | J7: =IF(I7<>"",D7*I7,"") -> 750000 | K7: =IF(J7<>"",IF(H7<>"",J7-H7,IF(F7<>"",J7-F7,"")),"") -> 100000 | L7: =IF(K7<>"",IF(H7<>"",IF(H7<>0,K7/H7,""),IF(F7<>"",IF(F7<>0,K7/F7,""),"")),"") -> 0.15384615
A8: 2 | B8: Plastik Es Wayang | C8: Pack | D8: 40 | F8: =IF(E8<>"",D8*E8,"") | G8: 13000 | H8: =IF(G8<>"",D8*G8,"") -> 520000 | I8: 17000 | J8: =IF(I8<>"",D8*I8,"") -> 680000 | K8: =IF(J8<>"",IF(H8<>"",J8-H8,IF(F8<>"",J8-F8,"")),"") -> 160000 | L8: =IF(K8<>"",IF(H8<>"",IF(H8<>0,K8/H8,""),IF(F8<>"",IF(F8<>0,K8/F8,""),"")),"") -> 0.30769231
A9: 3 | B9: Gas 50Kg | C9: Tabung | D9: 2 | F9: =IF(E9<>"",D9*E9,"") | G9: 1125000 | H9: =IF(G9<>"",D9*G9,"") -> 2250000 | I9: 1250000 | J9: =IF(I9<>"",D9*I9,"") -> 2500000 | K9: =IF(J9<>"",IF(H9<>"",J9-H9,IF(F9<>"",J9-F9,"")),"") -> 250000 | L9: =IF(K9<>"",IF(H9<>"",IF(H9<>0,K9/H9,""),IF(F9<>"",IF(F9<>0,K9/F9,""),"")),"") -> 0.11111111
A10: 4 | B10: Payung | C10: Pcs | D10: 5 | F10: =IF(E10<>"",D10*E10,"") | G10: 25500 | H10: =IF(G10<>"",D10*G10,"") -> 127500 | I10: 35000 | J10: =IF(I10<>"",D10*I10,"") -> 175000 | K10: =IF(J10<>"",IF(H10<>"",J10-H10,IF(F10<>"",J10-F10,"")),"") -> 47500 | L10: =IF(K10<>"",IF(H10<>"",IF(H10<>0,K10/H10,""),IF(F10<>"",IF(F10<>0,K10/F10,""),"")),"") -> 0.37254902
A11: 5 | B11: Kaporit Bubuk | C11: Ember | D11: 1 | F11: =IF(E11<>"",D11*E11,"") | G11: 470000 | H11: =IF(G11<>"",D11*G11,"") -> 470000 | I11: 500000 | J11: =IF(I11<>"",D11*I11,"") -> 500000 | K11: =IF(J11<>"",IF(H11<>"",J11-H11,IF(F11<>"",J11-F11,"")),"") -> 30000 | L11: =IF(K11<>"",IF(H11<>"",IF(H11<>0,K11/H11,""),IF(F11<>"",IF(F11<>0,K11/F11,""),"")),"") -> 0.063829787
A12: 6 | B12: Baygon | C12: Pcs | D12: 5 | F12: =IF(E12<>"",D12*E12,"") | G12: 34000 | H12: =IF(G12<>"",D12*G12,"") -> 170000 | I12: 38000 | J12: =IF(I12<>"",D12*I12,"") -> 190000 | K12: =IF(J12<>"",IF(H12<>"",J12-H12,IF(F12<>"",J12-F12,"")),"") -> 20000 | L12: =IF(K12<>"",IF(H12<>"",IF(H12<>0,K12/H12,""),IF(F12<>"",IF(F12<>0,K12/F12,""),"")),"") -> 0.11764706
A13: 7 | B13: Sabun Cuci Piring | C13: Drigen | D13: 10 | F13: =IF(E13<>"",D13*E13,"") | G13: 65000 | H13: =IF(G13<>"",D13*G13,"") -> 650000 | I13: 75000 | J13: =IF(I13<>"",D13*I13,"") -> 750000 | K13: =IF(J13<>"",IF(H13<>"",J13-H13,IF(F13<>"",J13-F13,"")),"") -> 100000 | L13: =IF(K13<>"",IF(H13<>"",IF(H13<>0,K13/H13,""),IF(F13<>"",IF(F13<>0,K13/F13,""),"")),"") -> 0.15384615
A14: SUBTOTAL 25 May 2026 | F14: =SUMIF(F7:F9,"<>",F7:F9) -> 0 | H14: =SUMIF(H7:H13,"<>",H7:H13) -> 4837500 | J14: =SUMIF(J7:J13,"<>",J7:J13) -> 5545000 | K14: =IF(J14<>"",IF(H14<>"",J14-H14,IF(F14<>"",J14-F14,"")),"") -> 707500 | L14: =IF(K14<>"",IF(H14<>"",IF(H14<>0,K14/H14,""),IF(F14<>"",IF(F14<>0,K14/F14,""),"")),"") -> 0.14625323
A17: 📅 Friday, 29 May 2026
A18: No | B18: Nama Barang | C18: Satuan | D18: Qty | E18: 📊 ESTIMASI | G18: 🧾 REALISASI BELI | I18: 💰 PENJUALAN | K18: 📈 MARGIN | M18: Keterangan
A19: No | B19: Nama Barang | C19: Satuan | D19: Qty | E19: Est. Harga Beli (Rp) | F19: Total Estimasi (Rp) | G19: Harga Beli Nota (Rp) | H19: Total Beli Nota (Rp) | I19: Harga Jual (Rp) | J19: Total Jual (Rp) | K19: Margin (Rp) | L19: Margin (%) | M19: Keterangan
A20: 1 | B20: Ember | C20: Pcs | D20: 4 | G20: 45000 | H20: =IF(G20<>"",D20*G20,"") -> 180000 | I20: 60000 | J20: =IF(I20<>"",D20*I20,"") -> 240000 | K20: =IF(J20<>"",IF(H20<>"",J20-H20,IF(F20<>"",J20-F20,"")),"") -> 60000 | L20: =IF(K20<>"",IF(H20<>"",IF(H20<>0,K20/H20,""),IF(F20<>"",IF(F20<>0,K20/F20,""),"")),"") -> 0.33333333
A21: 2 | B21: Gelas Plastik | C21: Lusin | D21: 1 | G21: 78000 | H21: =IF(G21<>"",D21*G21,"") -> 78000 | I21: 320000 | J21: =IF(I21<>"",D21*I21,"") -> 320000 | K21: =IF(J21<>"",IF(H21<>"",J21-H21,IF(F21<>"",J21-F21,"")),"") -> 242000 | L21: =IF(K21<>"",IF(H21<>"",IF(H21<>0,K21/H21,""),IF(F21<>"",IF(F21<>0,K21/F21,""),"")),"") -> 3.1025641
A22: 3 | B22: Gas 50Kg | C22: Tabung | D22: 1 | F22: =IF(E22<>"",D22*E22,"") | G22: 1125000 | H22: =IF(G22<>"",D22*G22,"") -> 1125000 | I22: 1250000 | J22: =IF(I22<>"",D22*I22,"") -> 1250000 | K22: =IF(J22<>"",IF(H22<>"",J22-H22,IF(F22<>"",J22-F22,"")),"") -> 125000 | L22: =IF(K22<>"",IF(H22<>"",IF(H22<>0,K22/H22,""),IF(F22<>"",IF(F22<>0,K22/F22,""),"")),"") -> 0.11111111
A23: SUBTOTAL 25 May 2026 | F23: =SUMIF(F20:F22,"<>",F20:F22) -> 0 | H23: =SUMIF(H20:H22,"<>",H20:H22) -> 1383000 | J23: =SUMIF(J20:J22,"<>",J20:J22) -> 1810000 | K23: =IF(J23<>"",IF(H23<>"",J23-H23,IF(F23<>"",J23-F23,"")),"") -> 427000 | L23: =IF(K23<>"",IF(H23<>"",IF(H23<>0,K23/H23,""),IF(F23<>"",IF(F23<>0,K23/F23,""),"")),"") -> 0.3087491
A25: 📅 Wednesday, 03 June 2026
A26: No | B26: Nama Barang | C26: Satuan | D26: Qty | E26: 📊 ESTIMASI | G26: 🧾 REALISASI BELI | I26: 💰 PENJUALAN | K26: 📈 MARGIN | M26: Keterangan
A27: No | B27: Nama Barang | C27: Satuan | D27: Qty | E27: Est. Harga Beli (Rp) | F27: Total Estimasi (Rp) | G27: Harga Beli Nota (Rp) | H27: Total Beli Nota (Rp) | I27: Harga Jual (Rp) | J27: Total Jual (Rp) | K27: Margin (Rp) | L27: Margin (%) | M27: Keterangan
A28: 1 | B28: Sarung Tangan Finnil | C28: Pack | D28: 10 | F28: =IF(E28<>"",D28*E28,"") | G28: 85000 | H28: =IF(G28<>"",D28*G28,"") -> 850000 | I28: 85000 | J28: =IF(I28<>"",D28*I28,"") -> 850000 | K28: =IF(J28<>"",IF(H28<>"",J28-H28,IF(F28<>"",J28-F28,"")),"") -> 0 | L28: =IF(K28<>"",IF(H28<>"",IF(H28<>0,K28/H28,""),IF(F28<>"",IF(F28<>0,K28/F28,""),"")),"") -> 0
A29: 2 | B29: Plastik Es wayang | C29: Pack | D29: 40 | F29: =IF(E29<>"",D29*E29,"") | G29: 9875 | H29: =IF(G29<>"",D29*G29,"") -> 395000 | I29: 17500 | J29: =IF(I29<>"",D29*I29,"") -> 700000 | K29: =IF(J29<>"",IF(H29<>"",J29-H29,IF(F29<>"",J29-F29,"")),"") -> 305000 | L29: =IF(K29<>"",IF(H29<>"",IF(H29<>0,K29/H29,""),IF(F29<>"",IF(F29<>0,K29/F29,""),"")),"") -> 0.7721519
A30: 3 | B30: Gas 50kg | C30: Tabung | D30: 2 | F30: =IF(E30<>"",D30*E30,"") | G30: 1125000 | H30: =IF(G30<>"",D30*G30,"") -> 2250000 | I30: 1250000 | J30: =IF(I30<>"",D30*I30,"") -> 2500000 | K30: =IF(J30<>"",IF(H30<>"",J30-H30,IF(F30<>"",J30-F30,"")),"") -> 250000 | L30: =IF(K30<>"",IF(H30<>"",IF(H30<>0,K30/H30,""),IF(F30<>"",IF(F30<>0,K30/F30,""),"")),"") -> 0.11111111
A31: 4 | B31: Sushi Roll | C31: Pcs | D31: 10 | F31: =IF(E31<>"",D31*E31,"") | G31: 27000 | H31: =IF(G31<>"",D31*G31,"") -> 270000 | I31: 30000 | J31: =IF(I31<>"",D31*I31,"") -> 300000 | K31: =IF(J31<>"",IF(H31<>"",J31-H31,IF(F31<>"",J31-F31,"")),"") -> 30000 | L31: =IF(K31<>"",IF(H31<>"",IF(H31<>0,K31/H31,""),IF(F31<>"",IF(F31<>0,K31/F31,""),"")),"") -> 0.11111111
A32: 5 | B32: MieSedap Goreng | C32: Dud | D32: 1 | F32: =IF(E32<>"",D32*E32,"") | G32: 124000 | H32: =IF(G32<>"",D32*G32,"") -> 124000 | I32: 150000 | J32: =IF(I32<>"",D32*I32,"") -> 150000 | K32: =IF(J32<>"",IF(H32<>"",J32-H32,IF(F32<>"",J32-F32,"")),"") -> 26000 | L32: =IF(K32<>"",IF(H32<>"",IF(H32<>0,K32/H32,""),IF(F32<>"",IF(F32<>0,K32/F32,""),"")),"") -> 0.20967742
A33: 6 | B33: Kopi Hitam Kapal api + gula | C33: Dus | D33: 1 | F33: =IF(E33<>"",D33*E33,"") | G33: 225000 | H33: =IF(G33<>"",D33*G33,"") -> 225000 | I33: 250000 | J33: =IF(I33<>"",D33*I33,"") -> 250000 | K33: =IF(J33<>"",IF(H33<>"",J33-H33,IF(F33<>"",J33-F33,"")),"") -> 25000 | L33: =IF(K33<>"",IF(H33<>"",IF(H33<>0,K33/H33,""),IF(F33<>"",IF(F33<>0,K33/F33,""),"")),"") -> 0.11111111
A34: 7 | B34: Gooday Merah | C34: Dus | D34: 1 | F34: =IF(E34<>"",D34*E34,"") | G34: 230000 | H34: =IF(G34<>"",D34*G34,"") -> 230000 | I34: 265000 | J34: =IF(I34<>"",D34*I34,"") -> 265000 | K34: =IF(J34<>"",IF(H34<>"",J34-H34,IF(F34<>"",J34-F34,"")),"") -> 35000 | L34: =IF(K34<>"",IF(H34<>"",IF(H34<>0,K34/H34,""),IF(F34<>"",IF(F34<>0,K34/F34,""),"")),"") -> 0.15217391
A35: 8 | B35: Gooday Freeze | C35: Dus | D35: 1 | F35: =IF(E35<>"",D35*E35,"") | G35: 302000 | H35: =IF(G35<>"",D35*G35,"") -> 302000 | I35: 330000 | J35: =IF(I35<>"",D35*I35,"") -> 330000 | K35: =IF(J35<>"",IF(H35<>"",J35-H35,IF(F35<>"",J35-F35,"")),"") -> 28000 | L35: =IF(K35<>"",IF(H35<>"",IF(H35<>0,K35/H35,""),IF(F35<>"",IF(F35<>0,K35/F35,""),"")),"") -> 0.092715232
A36: 9 | B36: Galon Aqua | C36: Galon | D36: 75 | F36: =IF(E36<>"",D36*E36,"") | G36: 19200 | H36: =IF(G36<>"",D36*G36,"") -> 1440000 | I36: 22500 | J36: =IF(I36<>"",D36*I36,"") -> 1687500 | K36: =IF(J36<>"",IF(H36<>"",J36-H36,IF(F36<>"",J36-F36,"")),"") -> 247500 | L36: =IF(K36<>"",IF(H36<>"",IF(H36<>0,K36/H36,""),IF(F36<>"",IF(F36<>0,K36/F36,""),"")),"") -> 0.171875
A37: 10 | B37: Sabun Cuci Piring | C37: Drigen | D37: 15 | F37: =IF(E37<>"",D37*E37,"") | G37: 65000 | H37: =IF(G37<>"",D37*G37,"") -> 975000 | I37: 75000 | J37: =IF(I37<>"",D37*I37,"") -> 1125000 | K37: =IF(J37<>"",IF(H37<>"",J37-H37,IF(F37<>"",J37-F37,"")),"") -> 150000 | L37: =IF(K37<>"",IF(H37<>"",IF(H37<>0,K37/H37,""),IF(F37<>"",IF(F37<>0,K37/F37,""),"")),"") -> 0.15384615
A38: 11 | B38: Thin Wall 200ml Bulat | C38: Pcs | D38: 2550 | F38: =IF(E38<>"",D38*E38,"") | G38: 540 | H38: =IF(G38<>"",D38*G38,"") -> 1377000 | I38: 750 | J38: =IF(I38<>"",D38*I38,"") -> 1912500 | K38: =IF(J38<>"",IF(H38<>"",J38-H38,IF(F38<>"",J38-F38,"")),"") -> 535500 | L38: =IF(K38<>"",IF(H38<>"",IF(H38<>0,K38/H38,""),IF(F38<>"",IF(F38<>0,K38/F38,""),"")),"") -> 0.38888889
A39: 12 | B39: Baygon | C39: Pcs | D39: 5 | F39: =IF(E39<>"",D39*E39,"") | G39: 32500 | H39: =IF(G39<>"",D39*G39,"") -> 162500 | I39: 37500 | J39: =IF(I39<>"",D39*I39,"") -> 187500 | K39: =IF(J39<>"",IF(H39<>"",J39-H39,IF(F39<>"",J39-F39,"")),"") -> 25000 | L39: =IF(K39<>"",IF(H39<>"",IF(H39<>0,K39/H39,""),IF(F39<>"",IF(F39<>0,K39/F39,""),"")),"") -> 0.15384615
A40: 13 | B40: Plester | C40: Pack | D40: 10 | G40: 35000 | H40: =IF(G40<>"",D40*G40,"") -> 350000 | I40: 45000 | J40: =IF(I40<>"",D40*I40,"") -> 450000
A41: 14 | B41: Karbol Untuk Toilet | C41: Pack | D41: 10 | G41: 27000 | H41: =IF(G41<>"",D41*G41,"") -> 270000 | I41: 35000 | J41: =IF(I41<>"",D41*I41,"") -> 350000
A42: 15 | B42: Gayung | C42: Pcs | D42: 5 | F42: =IF(E42<>"",D42*E42,"") | G42: 10000 | H42: =IF(G42<>"",D42*G42,"") -> 50000 | I42: 15000 | J42: =IF(I42<>"",D42*I42,"") -> 75000 | K42: =IF(J42<>"",IF(H42<>"",J42-H42,IF(F42<>"",J42-F42,"")),"") -> 25000 | L42: =IF(K42<>"",IF(H42<>"",IF(H42<>0,K42/H42,""),IF(F42<>"",IF(F42<>0,K42/F42,""),"")),"") -> 0.5
A43: 16 | B43: Thinwall Saos | C43: Pcs | D43: 2600 | F43: =IF(E43<>"",D43*E43,"") | G43: 225 | H43: =IF(G43<>"",D43*G43,"") -> 585000 | I43: 350 | J43: =IF(I43<>"",D43*I43,"") -> 910000 | K43: =IF(J43<>"",IF(H43<>"",J43-H43,IF(F43<>"",J43-F43,"")),"") -> 325000 | L43: =IF(K43<>"",IF(H43<>"",IF(H43<>0,K43/H43,""),IF(F43<>"",IF(F43<>0,K43/F43,""),"")),"") -> 0.55555556
...

Sheet Invoice B02
A1: 🧾 DRAFT INVOICE — BAKUNG 02
A2: Periode: Mei-Juni 2026 | 🟢 Hijau = linked Daftar Harga | 🔵 Biru = input manual (isi setelah nota datang)
A3: Kolom G (Harga Beli Nota) dikosongkan — isi saat barang tiba. Margin: pakai Nota jika ada, fallback ke Estimasi.
A4: 📅 Sunday, 24 May 2026
A5: No | B5: Nama Barang | C5: Satuan | D5: Qty | E5: 📊 ESTIMASI | G5: 🧾 REALISASI BELI | I5: 💰 PENJUALAN | K5: 📈 MARGIN | M5: Keterangan
A6: No | B6: Nama Barang | C6: Satuan | D6: Qty | E6: Est. Harga Beli (Rp) | F6: Total Estimasi (Rp) | G6: Harga Beli Nota (Rp) | H6: Total Beli Nota (Rp) | I6: Harga Jual (Rp) | J6: Total Jual (Rp) | K6: Margin (Rp) | L6: Margin (%) | M6: Keterangan
A7: 1 | B7: Ayam Potong Sayap | C7: Kg | D7: 215 | E7: ='Daftar Harga'!D10 -> 36500 | F7: =IF(E7<>"",D7*E7,"") -> 7847500 | G7: 33500 | H7: =IF(G7<>"",D7*G7,"") -> 7202500 | I7: 38000 | J7: =IF(I7<>"",D7*I7,"") -> 8170000 | K7: =IF(J7<>"",IF(H7<>"",J7-H7,IF(F7<>"",J7-F7,"")),"") -> 967500 | L7: =IF(K7<>"",IF(H7<>"",IF(H7<>0,K7/H7,""),IF(F7<>"",IF(F7<>0,K7/F7,""),"")),"") -> 0.13432836
A8: 2 | B8: Bawang Bombay | C8: Kg | D8: 2 | E8: ='Daftar Harga'!D12 -> 30000 | F8: =IF(E8<>"",D8*E8,"") -> 60000 | G8: 19000 | H8: =IF(G8<>"",D8*G8,"") -> 38000 | I8: 35000 | J8: =IF(I8<>"",D8*I8,"") -> 70000 | K8: =IF(J8<>"",IF(H8<>"",J8-H8,IF(F8<>"",J8-F8,"")),"") -> 32000 | L8: =IF(K8<>"",IF(H8<>"",IF(H8<>0,K8/H8,""),IF(F8<>"",IF(F8<>0,K8/F8,""),"")),"") -> 0.84210526
A9: 3 | B9: Bawang putih kupas | C9: Kg | D9: 5 | E9: ='Daftar Harga'!D16 -> 33000 | F9: =IF(E9<>"",D9*E9,"") -> 165000 | G9: 30000 | H9: =IF(G9<>"",D9*G9,"") -> 150000 | I9: 44000 | J9: =IF(I9<>"",D9*I9,"") -> 220000 | K9: =IF(J9<>"",IF(H9<>"",J9-H9,IF(F9<>"",J9-F9,"")),"") -> 70000 | L9: =IF(K9<>"",IF(H9<>"",IF(H9<>0,K9/H9,""),IF(F9<>"",IF(F9<>0,K9/F9,""),"")),"") -> 0.46666667
A10: 4 | B10: Beras | C10: Kg | D10: 130 | E10: ='Daftar Harga'!D17 -> 15500 | F10: =IF(E10<>"",D10*E10,"") -> 2015000 | G10: 14500 | H10: =IF(G10<>"",D10*G10,"") -> 1885000 | I10: 15500 | J10: =IF(I10<>"",D10*I10,"") -> 2015000 | K10: =IF(J10<>"",IF(H10<>"",J10-H10,IF(F10<>"",J10-F10,"")),"") -> 130000 | L10: =IF(K10<>"",IF(H10<>"",IF(H10<>0,K10/H10,""),IF(F10<>"",IF(F10<>0,K10/F10,""),"")),"") -> 0.068965517
A11: 5 | B11: Bubuk Cabe | C11: Kg | D11: 1 | E11: ='Daftar Harga'!D21 -> 170000 | F11: =IF(E11<>"",D11*E11,"") -> 170000 | G11: 85000 | H11: =IF(G11<>"",D11*G11,"") -> 85000 | I11: 105000 | J11: =IF(I11<>"",D11*I11,"") -> 105000 | K11: =IF(J11<>"",IF(H11<>"",J11-H11,IF(F11<>"",J11-F11,"")),"") -> 20000 | L11: =IF(K11<>"",IF(H11<>"",IF(H11<>0,K11/H11,""),IF(F11<>"",IF(F11<>0,K11/F11,""),"")),"") -> 0.23529412
A12: 6 | B12: Buncis | C12: Kg | D12: 30 | E12: ='Daftar Harga'!D24 -> 13000 | F12: =IF(E12<>"",D12*E12,"") -> 390000 | G12: 20000 | H12: =IF(G12<>"",D12*G12,"") -> 600000 | I12: 16000 | J12: =IF(I12<>"",D12*I12,"") -> 480000 | K12: =IF(J12<>"",IF(H12<>"",J12-H12,IF(F12<>"",J12-F12,"")),"") -> -120000 | L12: =IF(K12<>"",IF(H12<>"",IF(H12<>0,K12/H12,""),IF(F12<>"",IF(F12<>0,K12/F12,""),"")),"") -> -0.2
A13: 7 | B13: Cabai merah besar | C13: Kg | D13: 2 | E13: ='Daftar Harga'!D26 -> 47000 | F13: =IF(E13<>"",D13*E13,"") -> 94000 | G13: 70000 | H13: =IF(G13<>"",D13*G13,"") -> 140000 | I13: 75000 | J13: =IF(I13<>"",D13*I13,"") -> 150000 | K13: =IF(J13<>"",IF(H13<>"",J13-H13,IF(F13<>"",J13-F13,"")),"") -> 10000 | L13: =IF(K13<>"",IF(H13<>"",IF(H13<>0,K13/H13,""),IF(F13<>"",IF(F13<>0,K13/F13,""),"")),"") -> 0.071428571
A14: 8 | B14: Daun pandan | C14: Kg | D14: 0.25 | E14: ='Daftar Harga'!D31 -> 40000 | F14: =IF(E14<>"",D14*E14,"") -> 10000 | G14: 35000 | H14: =IF(G14<>"",D14*G14,"") -> 8750 | I14: 45000 | J14: =IF(I14<>"",D14*I14,"") -> 11250 | K14: =IF(J14<>"",IF(H14<>"",J14-H14,IF(F14<>"",J14-F14,"")),"") -> 2500 | L14: =IF(K14<>"",IF(H14<>"",IF(H14<>0,K14/H14,""),IF(F14<>"",IF(F14<>0,K14/F14,""),"")),"") -> 0.28571429
A15: 9 | B15: Gula pasir | C15: Kg | D15: 8 | E15: ='Daftar Harga'!D36 -> 19000 | F15: =IF(E15<>"",D15*E15,"") -> 152000 | G15: 18500 | H15: =IF(G15<>"",D15*G15,"") -> 148000 | I15: 20000 | J15: =IF(I15<>"",D15*I15,"") -> 160000 | K15: =IF(J15<>"",IF(H15<>"",J15-H15,IF(F15<>"",J15-F15,"")),"") -> 12000 | L15: =IF(K15<>"",IF(H15<>"",IF(H15<>0,K15/H15,""),IF(F15<>"",IF(F15<>0,K15/F15,""),"")),"") -> 0.081081081
A16: 10 | B16: Jahe | C16: Kg | D16: 1 | E16: ='Daftar Harga'!D39 -> 20000 | F16: =IF(E16<>"",D16*E16,"") -> 20000 | G16: 20000 | H16: =IF(G16<>"",D16*G16,"") -> 20000 | I16: 26000 | J16: =IF(I16<>"",D16*I16,"") -> 26000 | K16: =IF(J16<>"",IF(H16<>"",J16-H16,IF(F16<>"",J16-F16,"")),"") -> 6000 | L16: =IF(K16<>"",IF(H16<>"",IF(H16<>0,K16/H16,""),IF(F16<>"",IF(F16<>0,K16/F16,""),"")),"") -> 0.3
A17: 11 | B17: Kecap Inggris | C17: Botol | D17: 1 | E17: ='Daftar Harga'!D49 -> 47000 | F17: =IF(E17<>"",D17*E17,"") -> 47000 | G17: 47000 | H17: =IF(G17<>"",D17*G17,"") -> 47000 | I17: 55000 | J17: =IF(I17<>"",D17*I17,"") -> 55000 | K17: =IF(J17<>"",IF(H17<>"",J17-H17,IF(F17<>"",J17-F17,"")),"") -> 8000 | L17: =IF(K17<>"",IF(H17<>"",IF(H17<>0,K17/H17,""),IF(F17<>"",IF(F17<>0,K17/F17,""),"")),"") -> 0.17021277
A18: 12 | B18: Minyak | C18: Liter | D18: 72 | E18: ='Daftar Harga'!D69 -> 205000 | F18: =IF(E18<>"",D18*E18,"") -> 14760000 | G18: 22000 | H18: =IF(G18<>"",D18*G18,"") -> 1584000 | I18: 23000 | J18: =IF(I18<>"",D18*I18,"") -> 1656000 | K18: =IF(J18<>"",IF(H18<>"",J18-H18,IF(F18<>"",J18-F18,"")),"") -> 72000 | L18: =IF(K18<>"",IF(H18<>"",IF(H18<>0,K18/H18,""),IF(F18<>"",IF(F18<>0,K18/F18,""),"")),"") -> 0.045454545
A19: 13 | B19: Pisang | C19: Pcs | D19: 2020 | E19: ='Daftar Harga'!D71 -> 1900 | F19: =IF(E19<>"",D19*E19,"") -> 3838000 | G19: 1800 | H19: =IF(G19<>"",D19*G19,"") -> 3636000 | I19: 2000 | J19: =IF(I19<>"",D19*I19,"") -> 4040000 | K19: =IF(J19<>"",IF(H19<>"",J19-H19,IF(F19<>"",J19-F19,"")),"") -> 404000 | L19: =IF(K19<>"",IF(H19<>"",IF(H19<>0,K19/H19,""),IF(F19<>"",IF(F19<>0,K19/F19,""),"")),"") -> 0.11111111
A20: 14 | B20: Royko | C20: Kg | D20: 3 | E20: ='Daftar Harga'!D74 -> 42000 | F20: =IF(E20<>"",D20*E20,"") -> 126000 | G20: 42000 | H20: =IF(G20<>"",D20*G20,"") -> 126000 | I20: 46000 | J20: =IF(I20<>"",D20*I20,"") -> 138000 | K20: =IF(J20<>"",IF(H20<>"",J20-H20,IF(F20<>"",J20-F20,"")),"") -> 12000 | L20: =IF(K20<>"",IF(H20<>"",IF(H20<>0,K20/H20,""),IF(F20<>"",IF(F20<>0,K20/F20,""),"")),"") -> 0.095238095
A21: 15 | B21: Saus Pedas | C21: Dirigen | D21: 1 | E21: ='Daftar Harga'!D77 -> 135000 | F21: =IF(E21<>"",D21*E21,"") -> 135000 | G21: 115000 | H21: =IF(G21<>"",D21*G21,"") -> 115000 | I21: 130000 | J21: =IF(I21<>"",D21*I21,"") -> 130000 | K21: =IF(J21<>"",IF(H21<>"",J21-H21,IF(F21<>"",J21-F21,"")),"") -> 15000 | L21: =IF(K21<>"",IF(H21<>"",IF(H21<>0,K21/H21,""),IF(F21<>"",IF(F21<>0,K21/F21,""),"")),"") -> 0.13043478
A22: 16 | B22: Saus tiram | C22: Botol | D22: 2 | E22: ='Daftar Harga'!D79 -> 52000 | F22: =IF(E22<>"",D22*E22,"") -> 104000 | G22: 52000 | H22: =IF(G22<>"",D22*G22,"") -> 104000 | I22: 56000 | J22: =IF(I22<>"",D22*I22,"") -> 112000 | K22: =IF(J22<>"",IF(H22<>"",J22-H22,IF(F22<>"",J22-F22,"")),"") -> 8000 | L22: =IF(K22<>"",IF(H22<>"",IF(H22<>0,K22/H22,""),IF(F22<>"",IF(F22<>0,K22/F22,""),"")),"") -> 0.076923077
A23: 17 | B23: Saus tomat | C23: Dirigen | D23: 2 | E23: ='Daftar Harga'!D80 -> 95000 | F23: =IF(E23<>"",D23*E23,"") -> 190000 | G23: 95000 | H23: =IF(G23<>"",D23*G23,"") -> 190000 | I23: 110000 | J23: =IF(I23<>"",D23*I23,"") -> 220000 | K23: =IF(J23<>"",IF(H23<>"",J23-H23,IF(F23<>"",J23-F23,"")),"") -> 30000 | L23: =IF(K23<>"",IF(H23<>"",IF(H23<>0,K23/H23,""),IF(F23<>"",IF(F23<>0,K23/F23,""),"")),"") -> 0.15789474
A24: 18 | B24: Tahu Bulat | C24: Pcs | D24: 4000 | E24: ='Daftar Harga'!D89 -> 500 | F24: =IF(E24<>"",D24*E24,"") -> 2000000 | G24: 400 | H24: =IF(G24<>"",D24*G24,"") -> 1600000 | I24: 500 | J24: =IF(I24<>"",D24*I24,"") -> 2000000 | K24: =IF(J24<>"",IF(H24<>"",J24-H24,IF(F24<>"",J24-F24,"")),"") -> 400000 | L24: =IF(K24<>"",IF(H24<>"",IF(H24<>0,K24/H24,""),IF(F24<>"",IF(F24<>0,K24/F24,""),"")),"") -> 0.25
A25: 19 | B25: Wortel | C25: Kg | D25: 35 | E25: ='Daftar Harga'!D101 -> 9000 | F25: =IF(E25<>"",D25*E25,"") -> 315000 | G25: 12000 | H25: =IF(G25<>"",D25*G25,"") -> 420000 | I25: 14000 | J25: =IF(I25<>"",D25*I25,"") -> 490000 | K25: =IF(J25<>"",IF(H25<>"",J25-H25,IF(F25<>"",J25-F25,"")),"") -> 70000 | L25: =IF(K25<>"",IF(H25<>"",IF(H25<>0,K25/H25,""),IF(F25<>"",IF(F25<>0,K25/F25,""),"")),"") -> 0.16666667
A26: SUBTOTAL 24 May 2026 | F26: =SUMIF(F7:F25,"<>",F7:F25) -> 32438500 | H26: =SUMIF(H7:H25,"<>",H7:H25) -> 18099250 | J26: =SUMIF(J7:J25,"<>",J7:J25) -> 20248250 | K26: =IF(J26<>"",IF(H26<>"",J26-H26,IF(F26<>"",J26-F26,"")),"") -> 2149000 | L26: =IF(K26<>"",IF(H26<>"",IF(H26<>0,K26/H26,""),IF(F26<>"",IF(F26<>0,K26/F26,""),"")),"") -> 0.1187342
A28: 📅 Monday, 25 May 2026
A29: No | B29: Nama Barang | C29: Satuan | D29: Qty | E29: 📊 ESTIMASI | G29: 🧾 REALISASI BELI | I29: 💰 PENJUALAN | K29: 📈 MARGIN | M29: Keterangan
A30: No | B30: Nama Barang | C30: Satuan | D30: Qty | E30: Est. Harga Beli (Rp) | F30: Total Estimasi (Rp) | G30: Harga Beli Nota (Rp) | H30: Total Beli Nota (Rp) | I30: Harga Jual (Rp) | J30: Total Jual (Rp) | K30: Margin (Rp) | L30: Margin (%) | M30: Keterangan
A31: 1 | B31: Asam Jawa | C31: Kg | D31: 2 | E31: ='Daftar Harga'!D6 | F31: =IF(E31<>"",D31*E31,"") | G31: 20000 | H31: =IF(G31<>"",D31*G31,"") -> 40000 | I31: 23000 | J31: =IF(I31<>"",D31*I31,"") -> 46000 | K31: =IF(J31<>"",IF(H31<>"",J31-H31,IF(F31<>"",J31-F31,"")),"") -> 6000 | L31: =IF(K31<>"",IF(H31<>"",IF(H31<>0,K31/H31,""),IF(F31<>"",IF(F31<>0,K31/F31,""),"")),"") -> 0.15
A32: 2 | B32: Bawang merah kupas | C32: Kg | D32: 8 | E32: ='Daftar Harga'!D14 -> 40000 | F32: =IF(E32<>"",D32*E32,"") -> 320000 | G32: 40000 | H32: =IF(G32<>"",D32*G32,"") -> 320000 | I32: 45000 | J32: =IF(I32<>"",D32*I32,"") -> 360000 | K32: =IF(J32<>"",IF(H32<>"",J32-H32,IF(F32<>"",J32-F32,"")),"") -> 40000 | L32: =IF(K32<>"",IF(H32<>"",IF(H32<>0,K32/H32,""),IF(F32<>"",IF(F32<>0,K32/F32,""),"")),"") -> 0.125
A33: 3 | B33: Bawang putih kupas | C33: Kg | D33: 5 | E33: ='Daftar Harga'!D16 -> 33000 | F33: =IF(E33<>"",D33*E33,"") -> 165000 | G33: 30000 | H33: =IF(G33<>"",D33*G33,"") -> 150000 | I33: 40000 | J33: =IF(I33<>"",D33*I33,"") -> 200000 | K33: =IF(J33<>"",IF(H33<>"",J33-H33,IF(F33<>"",J33-F33,"")),"") -> 50000 | L33: =IF(K33<>"",IF(H33<>"",IF(H33<>0,K33/H33,""),IF(F33<>"",IF(F33<>0,K33/F33,""),"")),"") -> 0.33333333
A34: 4 | B34: Beras | C34: Kg | D34: 130 | E34: ='Daftar Harga'!D17 -> 15500 | F34: =IF(E34<>"",D34*E34,"") -> 2015000 | G34: 14500 | H34: =IF(G34<>"",D34*G34,"") -> 1885000 | I34: 15500 | J34: =IF(I34<>"",D34*I34,"") -> 2015000 | K34: =IF(J34<>"",IF(H34<>"",J34-H34,IF(F34<>"",J34-F34,"")),"") -> 130000 | L34: =IF(K34<>"",IF(H34<>"",IF(H34<>0,K34/H34,""),IF(F34<>"",IF(F34<>0,K34/F34,""),"")),"") -> 0.068965517
